[*] Načítám seznam archivních stránek z homepage…
Traceback (most recent call last):
  File "/Users/patrickzandl/Documents/GitHub/brandys-pirati/export_env/lib/python3.13/site-packages/urllib3/connection.py", line 198, in _new_conn
    sock = connection.create_connection(
        (self._dns_host, self.port),
    ...<2 lines>...
        socket_options=self.socket_options,
    )
  File "/Users/patrickzandl/Documents/GitHub/brandys-pirati/export_env/lib/python3.13/site-packages/urllib3/util/connection.py", line 85, in create_connection
    raise err
  File "/Users/patrickzandl/Documents/GitHub/brandys-pirati/export_env/lib/python3.13/site-packages/urllib3/util/connection.py", line 73, in create_connection
    sock.connect(sa)
    ~~~~~~~~~~~~^^^^
ConnectionRefusedError: [Errno 61] Connection refused

The above exception was the direct cause of the following exception:

Traceback (most recent call last):
  File "/Users/patrickzandl/Documents/GitHub/brandys-pirati/export_env/lib/python3.13/site-packages/urllib3/connectionpool.py", line 787, in urlopen
    response = self._make_request(
        conn,
    ...<10 lines>...
        **response_kw,
    )
  File "/Users/patrickzandl/Documents/GitHub/brandys-pirati/export_env/lib/python3.13/site-packages/urllib3/connectionpool.py", line 488, in _make_request
    raise new_e
  File "/Users/patrickzandl/Documents/GitHub/brandys-pirati/export_env/lib/python3.13/site-packages/urllib3/connectionpool.py", line 464, in _make_request
    self._validate_conn(conn)
    ~~~~~~~~~~~~~~~~~~~^^^^^^
  File "/Users/patrickzandl/Documents/GitHub/brandys-pirati/export_env/lib/python3.13/site-packages/urllib3/connectionpool.py", line 1093, in _validate_conn
    conn.connect()
    ~~~~~~~~~~~~^^
  File "/Users/patrickzandl/Documents/GitHub/brandys-pirati/export_env/lib/python3.13/site-packages/urllib3/connection.py", line 753, in connect
    self.sock = sock = self._new_conn()
                       ~~~~~~~~~~~~~~^^
  File "/Users/patrickzandl/Documents/GitHub/brandys-pirati/export_env/lib/python3.13/site-packages/urllib3/connection.py", line 213, in _new_conn
    raise NewConnectionError(
        self, f"Failed to establish a new connection: {e}"
    ) from e
urllib3.exceptions.NewConnectionError: <urllib3.connection.HTTPSConnection object at 0x105a1eba0>: Failed to establish a new connection: [Errno 61] Connection refused

The above exception was the direct cause of the following exception:

Traceback (most recent call last):
  File "/Users/patrickzandl/Documents/GitHub/brandys-pirati/export_env/lib/python3.13/site-packages/requests/adapters.py", line 667, in send
    resp = conn.urlopen(
        method=request.method,
    ...<9 lines>...
        chunked=chunked,
    )
  File "/Users/patrickzandl/Documents/GitHub/brandys-pirati/export_env/lib/python3.13/site-packages/urllib3/connectionpool.py", line 841, in urlopen
    retries = retries.increment(
        method, url, error=new_e, _pool=self, _stacktrace=sys.exc_info()[2]
    )
  File "/Users/patrickzandl/Documents/GitHub/brandys-pirati/export_env/lib/python3.13/site-packages/urllib3/util/retry.py", line 519, in increment
    raise MaxRetryError(_pool, url, reason) from reason  # type: ignore[arg-type]
    ^^^^^^^^^^^^^^^^^^^^^^^^^^^^^^^^^^^^^^^^^^^^^^^^^^^
urllib3.exceptions.MaxRetryError: HTTPSConnectionPool(host='web.archive.org', port=443): Max retries exceeded with url: /web/20230330073311/https://www.piratibrandys.cz/ (Caused by NewConnectionError('<urllib3.connection.HTTPSConnection object at 0x105a1eba0>: Failed to establish a new connection: [Errno 61] Connection refused'))

During handling of the above exception, another exception occurred:

Traceback (most recent call last):
  File "/Users/patrickzandl/Documents/GitHub/brandys-pirati/export.py", line 291, in <module>
    main()
    ~~~~^^
  File "/Users/patrickzandl/Documents/GitHub/brandys-pirati/export.py", line 242, in main
    month_links = discover_archive_month_links(WAYBACK_START)
  File "/Users/patrickzandl/Documents/GitHub/brandys-pirati/export.py", line 44, in discover_archive_month_links
    soup = get_soup(start_url)
  File "/Users/patrickzandl/Documents/GitHub/brandys-pirati/export.py", line 38, in get_soup
    r = requests.get(url, headers=HEADERS, timeout=30)
  File "/Users/patrickzandl/Documents/GitHub/brandys-pirati/export_env/lib/python3.13/site-packages/requests/api.py", line 73, in get
    return request("get", url, params=params, **kwargs)
  File "/Users/patrickzandl/Documents/GitHub/brandys-pirati/export_env/lib/python3.13/site-packages/requests/api.py", line 59, in request
    return session.request(method=method, url=url, **kwargs)
           ~~~~~~~~~~~~~~~^^^^^^^^^^^^^^^^^^^^^^^^^^^^^^^^^^
  File "/Users/patrickzandl/Documents/GitHub/brandys-pirati/export_env/lib/python3.13/site-packages/requests/sessions.py", line 589, in request
    resp = self.send(prep, **send_kwargs)
  File "/Users/patrickzandl/Documents/GitHub/brandys-pirati/export_env/lib/python3.13/site-packages/requests/sessions.py", line 703, in send
    r = adapter.send(request, **kwargs)
  File "/Users/patrickzandl/Documents/GitHub/brandys-pirati/export_env/lib/python3.13/site-packages/requests/adapters.py", line 700, in send
    raise ConnectionError(e, request=request)
requests.exceptions.ConnectionError: HTTPSConnectionPool(host='web.archive.org', port=443): Max retries exceeded with url: /web/20230330073311/https://www.piratibrandys.cz/ (Caused by NewConnectionError('<urllib3.connection.HTTPSConnection object at 0x105a1eba0>: Failed to establish a new connection: [Errno 61] Connection refused'))
